### 20190924
---

```csharp
private async Task ErrorAsync()
{
    try
    {
		// Task A
        try
        {
			// Task B
            try
            {
				// Task C
                try
                {
                    // Task D
                }
                catch (Exception ex)
                {
                    if (_isBusy)
                        _logger.Fatal(ex);
                }
            }
            catch (Exception ex)
            {
                if (_isBusy)
                    _logger.Fatal(ex);
            }
        }
        catch (Exception ex)
        {
            _logger.Error(ex);
        }
    }
    catch (Exception ex)
    {
        _logger.Error(ex);
    }
}
```

위 함수는 테스트를 위한 구조이며, logger레벨도 테스트로 저렇게 막 넣은 것이니 실제로는 저렇게 구현하지 않는다.

`try ~ catch` 스코프안에서 `_isBusy`의 조건에 충족할 때, 로그를 남기려고 한다.
`Task C`를 하는데 `try ~ catch`에서 예외처리가 되면 `if (_isBusy)`을 충족하면 로그를 쌓거나, 충족하지 않으면 로그를 쌓지 않고 `Task A`, `Task B`, `Task D`에서의 예외처리는 무시된다.
그리고 `throw Exception`로 예외처리를 호출한 곳으로 넘기면 그 호출한 곳에서 예외처리를 받아서 처리할 수 있다.